{"id": "7b3bb2af-a056-482e-bf09-c627b7068a0c", "timestamp": "2025-08-01T21:11:52.001023", "level": "info", "category": "system", "user_id": "default", "session_id": "default", "action": "memory_loaded", "details": {"type": "all", "files_loaded": 5}, "duration_ms": null, "success": true, "error_message": null, "metadata": null}
{"id": "a1343886-051f-41a6-8134-b49f2788d52e", "timestamp": "2025-08-01T21:12:26.412970", "level": "info", "category": "system", "user_id": "default", "session_id": "default", "action": "memory_loaded", "details": {"type": "all", "files_loaded": 5}, "duration_ms": null, "success": true, "error_message": null, "metadata": null}
{"id": "3aa73e83-703d-44b0-84ef-cca9a26a1b9c", "timestamp": "2025-08-01T21:12:26.427719", "level": "info", "category": "system", "user_id": "default", "session_id": "default", "action": "watchdog_started", "details": {"interval": 60, "enabled": true}, "duration_ms": null, "success": true, "error_message": null, "metadata": null}
{"id": "41180819-45ff-40be-b577-c676398b3659", "timestamp": "2025-08-01T21:12:27.916219", "level": "critical", "category": "system", "user_id": "default", "session_id": "default", "action": "critical_failure", "details": {"failures": [{"name": "backend_api", "message": "Backend API unreachable: HTTPConnectionPool(host='localhost', port=5000): Max retries exceeded with url: /health (Caused by NewConnectionError('<urllib3.connection.HTTPConnection object at 0x7f1d6cf98dd0>: Failed to establish a new connection: [Errno 111] Connection refused'))"}, {"name": "openai_api", "message": "OpenAI API unavailable: Error code: 404 - {'status': 'not found'}"}], "recovery_attempted": true}, "duration_ms": null, "success": false, "error_message": null, "metadata": null}
{"id": "9e490a20-77a7-4734-83a6-680529ddd471", "timestamp": "2025-08-01T21:17:45.548759", "level": "info", "category": "system", "user_id": "default", "session_id": "default", "action": "memory_loaded", "details": {"type": "all", "files_loaded": 5}, "duration_ms": null, "success": true, "error_message": null, "metadata": null}
{"id": "4bb2191a-fbc5-446d-988d-7ad58d3ff30a", "timestamp": "2025-08-01T21:17:45.559679", "level": "info", "category": "system", "user_id": "default", "session_id": "default", "action": "watchdog_started", "details": {"interval": 60, "enabled": true}, "duration_ms": null, "success": true, "error_message": null, "metadata": null}
{"id": "b51a2e93-08c3-4268-83f6-8fa60986528e", "timestamp": "2025-08-01T21:17:45.570866", "level": "info", "category": "auth", "user_id": "system", "session_id": "default", "action": "api_key_created", "details": {"key_id": "447f8ec9-0605-4027-8b93-12236d835fe7", "name": "Default Admin Key", "permissions": ["chat", "execute", "upload", "status", "mode", "admin"]}, "duration_ms": null, "success": true, "error_message": null, "metadata": null}
{"id": "3d82b124-1406-4cb9-9603-31bac2d425d7", "timestamp": "2025-08-01T21:17:46.911147", "level": "critical", "category": "system", "user_id": "default", "session_id": "default", "action": "critical_failure", "details": {"failures": [{"name": "backend_api", "message": "Backend API unreachable: HTTPConnectionPool(host='localhost', port=5000): Max retries exceeded with url: /health (Caused by NewConnectionError('<urllib3.connection.HTTPConnection object at 0x7f33e2375d50>: Failed to establish a new connection: [Errno 111] Connection refused'))"}, {"name": "openai_api", "message": "OpenAI API unavailable: Error code: 404 - {'status': 'not found'}"}], "recovery_attempted": true}, "duration_ms": null, "success": false, "error_message": null, "metadata": null}
{"id": "c7e1ebc6-0ef9-4016-afe8-bf8ccc8eaa64", "timestamp": "2025-08-01T21:24:16.413458", "level": "info", "category": "system", "user_id": "default", "session_id": "default", "action": "memory_loaded", "details": {"type": "all", "files_loaded": 5}, "duration_ms": null, "success": true, "error_message": null, "metadata": null}
{"id": "eb1471a2-e4c8-44db-bcb1-0e6a9916aa35", "timestamp": "2025-08-01T21:24:16.424110", "level": "info", "category": "system", "user_id": "default", "session_id": "default", "action": "watchdog_started", "details": {"interval": 60, "enabled": true}, "duration_ms": null, "success": true, "error_message": null, "metadata": null}
{"id": "c3d70ade-8691-4bd8-8cf5-76e689507155", "timestamp": "2025-08-01T21:24:17.768403", "level": "critical", "category": "system", "user_id": "default", "session_id": "default", "action": "critical_failure", "details": {"failures": [{"name": "backend_api", "message": "Backend API unreachable: HTTPConnectionPool(host='localhost', port=5000): Max retries exceeded with url: /health (Caused by NewConnectionError('<urllib3.connection.HTTPConnection object at 0x7f563578ebd0>: Failed to establish a new connection: [Errno 111] Connection refused'))"}, {"name": "openai_api", "message": "OpenAI API unavailable: Error code: 404 - {'status': 'not found'}"}], "recovery_attempted": true}, "duration_ms": null, "success": false, "error_message": null, "metadata": null}
{"id": "8efa23e5-ccb7-4ed7-a518-bd01c9fb936f", "timestamp": "2025-08-01T21:35:07.885088", "level": "info", "category": "system", "user_id": "default", "session_id": "default", "action": "memory_loaded", "details": {"type": "all", "files_loaded": 5}, "duration_ms": null, "success": true, "error_message": null, "metadata": null}
{"id": "d05d765f-972e-48c3-9f4b-7ba9f6f731dc", "timestamp": "2025-08-01T21:35:07.895832", "level": "info", "category": "system", "user_id": "default", "session_id": "default", "action": "watchdog_started", "details": {"interval": 60, "enabled": true}, "duration_ms": null, "success": true, "error_message": null, "metadata": null}
{"id": "6d0d948a-e6a4-49c2-8d92-da5bb3a11302", "timestamp": "2025-08-01T21:35:09.295855", "level": "critical", "category": "system", "user_id": "default", "session_id": "default", "action": "critical_failure", "details": {"failures": [{"name": "backend_api", "message": "Backend API unreachable: HTTPConnectionPool(host='localhost', port=5000): Max retries exceeded with url: /health (Caused by NewConnectionError('<urllib3.connection.HTTPConnection object at 0x7f24ce9c8dd0>: Failed to establish a new connection: [Errno 111] Connection refused'))"}, {"name": "openai_api", "message": "OpenAI API unavailable: Error code: 404 - {'status': 'not found'}"}], "recovery_attempted": true}, "duration_ms": null, "success": false, "error_message": null, "metadata": null}
